INFO:     Will watch for changes in these directories: ['/home/utkarshr_ug22_cs/QuantasticaAPI/ai']
INFO:     Uvicorn running on http://0.0.0.0:8001 (Press CTRL+C to quit)
INFO:     Started reloader process [36817] using StatReload
Process SpawnProcess-1:
Traceback (most recent call last):
  File "/usr/lib/python3.11/multiprocessing/process.py", line 314, in _bootstrap
    self.run()
  File "/usr/lib/python3.11/multiprocessing/process.py", line 108, in run
    self._target(*self._args, **self._kwargs)
  File "/home/utkarshr_ug22_cs/QuantasticaAPI/ai/.venv/lib/python3.11/site-packages/uvicorn/_subprocess.py", line 80, in subprocess_started
    target(sockets=sockets)
  File "/home/utkarshr_ug22_cs/QuantasticaAPI/ai/.venv/lib/python3.11/site-packages/uvicorn/server.py", line 67, in run
    return asyncio.run(self.serve(sockets=sockets))
           ^^^^^^^^^^^^^^^^^^^^^^^^^^^^^^^^^^^^^^^^
  File "/usr/lib/python3.11/asyncio/runners.py", line 190, in run
    return runner.run(main)
           ^^^^^^^^^^^^^^^^
  File "/usr/lib/python3.11/asyncio/runners.py", line 118, in run
    return self._loop.run_until_complete(task)
           ^^^^^^^^^^^^^^^^^^^^^^^^^^^^^^^^^^^
  File "/usr/lib/python3.11/asyncio/base_events.py", line 653, in run_until_complete
    return future.result()
           ^^^^^^^^^^^^^^^
  File "/home/utkarshr_ug22_cs/QuantasticaAPI/ai/.venv/lib/python3.11/site-packages/uvicorn/server.py", line 71, in serve
    await self._serve(sockets)
  File "/home/utkarshr_ug22_cs/QuantasticaAPI/ai/.venv/lib/python3.11/site-packages/uvicorn/server.py", line 78, in _serve
    config.load()
  File "/home/utkarshr_ug22_cs/QuantasticaAPI/ai/.venv/lib/python3.11/site-packages/uvicorn/config.py", line 436, in load
    self.loaded_app = import_from_string(self.app)
                      ^^^^^^^^^^^^^^^^^^^^^^^^^^^^
  File "/home/utkarshr_ug22_cs/QuantasticaAPI/ai/.venv/lib/python3.11/site-packages/uvicorn/importer.py", line 22, in import_from_string
    raise exc from None
  File "/home/utkarshr_ug22_cs/QuantasticaAPI/ai/.venv/lib/python3.11/site-packages/uvicorn/importer.py", line 19, in import_from_string
    module = importlib.import_module(module_str)
             ^^^^^^^^^^^^^^^^^^^^^^^^^^^^^^^^^^^
  File "/usr/lib/python3.11/importlib/__init__.py", line 126, in import_module
    return _bootstrap._gcd_import(name[level:], package, level)
           ^^^^^^^^^^^^^^^^^^^^^^^^^^^^^^^^^^^^^^^^^^^^^^^^^^^^
  File "<frozen importlib._bootstrap>", line 1206, in _gcd_import
  File "<frozen importlib._bootstrap>", line 1178, in _find_and_load
  File "<frozen importlib._bootstrap>", line 1149, in _find_and_load_unlocked
  File "<frozen importlib._bootstrap>", line 690, in _load_unlocked
  File "<frozen importlib._bootstrap_external>", line 940, in exec_module
  File "<frozen importlib._bootstrap>", line 241, in _call_with_frames_removed
  File "/home/utkarshr_ug22_cs/QuantasticaAPI/ai/app/main.py", line 2, in <module>
    from app.api.routes import voice, finance, group, prompt
  File "/home/utkarshr_ug22_cs/QuantasticaAPI/ai/app/api/routes/voice.py", line 4, in <module>
    from app.agents.voice_agent import VoiceAgent
ModuleNotFoundError: No module named 'app.agents.voice_agent'
WARNING:  StatReload detected changes in 'app/main.py'. Reloading...
Process SpawnProcess-2:
Traceback (most recent call last):
  File "/usr/lib/python3.11/multiprocessing/process.py", line 314, in _bootstrap
    self.run()
  File "/usr/lib/python3.11/multiprocessing/process.py", line 108, in run
    self._target(*self._args, **self._kwargs)
  File "/home/utkarshr_ug22_cs/QuantasticaAPI/ai/.venv/lib/python3.11/site-packages/uvicorn/_subprocess.py", line 80, in subprocess_started
    target(sockets=sockets)
  File "/home/utkarshr_ug22_cs/QuantasticaAPI/ai/.venv/lib/python3.11/site-packages/uvicorn/server.py", line 67, in run
    return asyncio.run(self.serve(sockets=sockets))
           ^^^^^^^^^^^^^^^^^^^^^^^^^^^^^^^^^^^^^^^^
  File "/usr/lib/python3.11/asyncio/runners.py", line 190, in run
    return runner.run(main)
           ^^^^^^^^^^^^^^^^
  File "/usr/lib/python3.11/asyncio/runners.py", line 118, in run
    return self._loop.run_until_complete(task)
           ^^^^^^^^^^^^^^^^^^^^^^^^^^^^^^^^^^^
  File "/usr/lib/python3.11/asyncio/base_events.py", line 653, in run_until_complete
    return future.result()
           ^^^^^^^^^^^^^^^
  File "/home/utkarshr_ug22_cs/QuantasticaAPI/ai/.venv/lib/python3.11/site-packages/uvicorn/server.py", line 71, in serve
    await self._serve(sockets)
  File "/home/utkarshr_ug22_cs/QuantasticaAPI/ai/.venv/lib/python3.11/site-packages/uvicorn/server.py", line 78, in _serve
    config.load()
  File "/home/utkarshr_ug22_cs/QuantasticaAPI/ai/.venv/lib/python3.11/site-packages/uvicorn/config.py", line 436, in load
    self.loaded_app = import_from_string(self.app)
                      ^^^^^^^^^^^^^^^^^^^^^^^^^^^^
  File "/home/utkarshr_ug22_cs/QuantasticaAPI/ai/.venv/lib/python3.11/site-packages/uvicorn/importer.py", line 22, in import_from_string
    raise exc from None
  File "/home/utkarshr_ug22_cs/QuantasticaAPI/ai/.venv/lib/python3.11/site-packages/uvicorn/importer.py", line 19, in import_from_string
    module = importlib.import_module(module_str)
             ^^^^^^^^^^^^^^^^^^^^^^^^^^^^^^^^^^^
  File "/usr/lib/python3.11/importlib/__init__.py", line 126, in import_module
    return _bootstrap._gcd_import(name[level:], package, level)
           ^^^^^^^^^^^^^^^^^^^^^^^^^^^^^^^^^^^^^^^^^^^^^^^^^^^^
  File "<frozen importlib._bootstrap>", line 1206, in _gcd_import
  File "<frozen importlib._bootstrap>", line 1178, in _find_and_load
  File "<frozen importlib._bootstrap>", line 1149, in _find_and_load_unlocked
  File "<frozen importlib._bootstrap>", line 690, in _load_unlocked
  File "<frozen importlib._bootstrap_external>", line 940, in exec_module
  File "<frozen importlib._bootstrap>", line 241, in _call_with_frames_removed
  File "/home/utkarshr_ug22_cs/QuantasticaAPI/ai/app/main.py", line 2, in <module>
    from app.api.routes import finance, group, prompt
  File "/home/utkarshr_ug22_cs/QuantasticaAPI/ai/app/api/routes/finance.py", line 4, in <module>
    from app.agents.personal_advisor_agent import PersonalAdvisorAgent
ModuleNotFoundError: No module named 'app.agents.personal_advisor_agent'
INFO:     Will watch for changes in these directories: ['/home/utkarshr_ug22_cs/QuantasticaAPI/ai']
INFO:     Uvicorn running on http://0.0.0.0:8001 (Press CTRL+C to quit)
INFO:     Started reloader process [36829] using StatReload
Process SpawnProcess-1:
Traceback (most recent call last):
  File "/usr/lib/python3.11/multiprocessing/process.py", line 314, in _bootstrap
    self.run()
  File "/usr/lib/python3.11/multiprocessing/process.py", line 108, in run
    self._target(*self._args, **self._kwargs)
  File "/home/utkarshr_ug22_cs/QuantasticaAPI/ai/.venv/lib/python3.11/site-packages/uvicorn/_subprocess.py", line 80, in subprocess_started
    target(sockets=sockets)
  File "/home/utkarshr_ug22_cs/QuantasticaAPI/ai/.venv/lib/python3.11/site-packages/uvicorn/server.py", line 67, in run
    return asyncio.run(self.serve(sockets=sockets))
           ^^^^^^^^^^^^^^^^^^^^^^^^^^^^^^^^^^^^^^^^
  File "/usr/lib/python3.11/asyncio/runners.py", line 190, in run
    return runner.run(main)
           ^^^^^^^^^^^^^^^^
  File "/usr/lib/python3.11/asyncio/runners.py", line 118, in run
    return self._loop.run_until_complete(task)
           ^^^^^^^^^^^^^^^^^^^^^^^^^^^^^^^^^^^
  File "/usr/lib/python3.11/asyncio/base_events.py", line 653, in run_until_complete
    return future.result()
           ^^^^^^^^^^^^^^^
  File "/home/utkarshr_ug22_cs/QuantasticaAPI/ai/.venv/lib/python3.11/site-packages/uvicorn/server.py", line 71, in serve
    await self._serve(sockets)
  File "/home/utkarshr_ug22_cs/QuantasticaAPI/ai/.venv/lib/python3.11/site-packages/uvicorn/server.py", line 78, in _serve
    config.load()
  File "/home/utkarshr_ug22_cs/QuantasticaAPI/ai/.venv/lib/python3.11/site-packages/uvicorn/config.py", line 436, in load
    self.loaded_app = import_from_string(self.app)
                      ^^^^^^^^^^^^^^^^^^^^^^^^^^^^
  File "/home/utkarshr_ug22_cs/QuantasticaAPI/ai/.venv/lib/python3.11/site-packages/uvicorn/importer.py", line 22, in import_from_string
    raise exc from None
  File "/home/utkarshr_ug22_cs/QuantasticaAPI/ai/.venv/lib/python3.11/site-packages/uvicorn/importer.py", line 19, in import_from_string
    module = importlib.import_module(module_str)
             ^^^^^^^^^^^^^^^^^^^^^^^^^^^^^^^^^^^
  File "/usr/lib/python3.11/importlib/__init__.py", line 126, in import_module
    return _bootstrap._gcd_import(name[level:], package, level)
           ^^^^^^^^^^^^^^^^^^^^^^^^^^^^^^^^^^^^^^^^^^^^^^^^^^^^
  File "<frozen importlib._bootstrap>", line 1206, in _gcd_import
  File "<frozen importlib._bootstrap>", line 1178, in _find_and_load
  File "<frozen importlib._bootstrap>", line 1149, in _find_and_load_unlocked
  File "<frozen importlib._bootstrap>", line 690, in _load_unlocked
  File "<frozen importlib._bootstrap_external>", line 940, in exec_module
  File "<frozen importlib._bootstrap>", line 241, in _call_with_frames_removed
  File "/home/utkarshr_ug22_cs/QuantasticaAPI/ai/app/main.py", line 2, in <module>
    from app.api.routes import finance, group, prompt
  File "/home/utkarshr_ug22_cs/QuantasticaAPI/ai/app/api/routes/finance.py", line 4, in <module>
    from app.agents.personal_advisor_agent import PersonalAdvisorAgent
ModuleNotFoundError: No module named 'app.agents.personal_advisor_agent'
INFO:     Stopping reloader process [36817]
INFO:     Stopping reloader process [36829]
INFO:     Will watch for changes in these directories: ['/home/utkarshr_ug22_cs/QuantasticaAPI/ai']
INFO:     Uvicorn running on http://0.0.0.0:8001 (Press CTRL+C to quit)
INFO:     Started reloader process [37518] using StatReload
INFO:     Started server process [37520]
INFO:     Waiting for application startup.
INFO:     Application startup complete.
WARNING:  StatReload detected changes in 'app/api/routes/finance.py'. Reloading...
INFO:     Shutting down
INFO:     Waiting for application shutdown.
INFO:     Application shutdown complete.
INFO:     Finished server process [37520]
INFO:     Started server process [37537]
INFO:     Waiting for application startup.
INFO:     Application startup complete.
WARNING:  StatReload detected changes in 'app/api/routes/voice.py'. Reloading...
INFO:     Shutting down
INFO:     Waiting for application shutdown.
INFO:     Application shutdown complete.
INFO:     Finished server process [37537]
INFO:     Started server process [37544]
INFO:     Waiting for application startup.
INFO:     Application startup complete.
INFO:     Shutting down
INFO:     Waiting for application shutdown.
INFO:     Application shutdown complete.
INFO:     Finished server process [37544]
INFO:     Stopping reloader process [37518]
INFO:     Will watch for changes in these directories: ['/home/utkarshr_ug22_cs/QuantasticaAPI/ai']
INFO:     Uvicorn running on http://0.0.0.0:8001 (Press CTRL+C to quit)
INFO:     Started reloader process [37547] using StatReload
INFO:     Started server process [37549]
INFO:     Waiting for application startup.
INFO:     Application startup complete.
INFO:     223.237.160.83:34337 - "POST /prompt/financial_analyzer HTTP/1.1" 500 Internal Server Error
ERROR:    Exception in ASGI application
Traceback (most recent call last):
  File "/home/utkarshr_ug22_cs/QuantasticaAPI/ai/.venv/lib/python3.11/site-packages/uvicorn/protocols/http/h11_impl.py", line 403, in run_asgi
    result = await app(  # type: ignore[func-returns-value]
             ^^^^^^^^^^^^^^^^^^^^^^^^^^^^^^^^^^^^^^^^^^^^^^
  File "/home/utkarshr_ug22_cs/QuantasticaAPI/ai/.venv/lib/python3.11/site-packages/uvicorn/middleware/proxy_headers.py", line 60, in __call__
    return await self.app(scope, receive, send)
           ^^^^^^^^^^^^^^^^^^^^^^^^^^^^^^^^^^^^
  File "/home/utkarshr_ug22_cs/QuantasticaAPI/ai/.venv/lib/python3.11/site-packages/fastapi/applications.py", line 1054, in __call__
    await super().__call__(scope, receive, send)
  File "/home/utkarshr_ug22_cs/QuantasticaAPI/ai/.venv/lib/python3.11/site-packages/starlette/applications.py", line 113, in __call__
    await self.middleware_stack(scope, receive, send)
  File "/home/utkarshr_ug22_cs/QuantasticaAPI/ai/.venv/lib/python3.11/site-packages/starlette/middleware/errors.py", line 186, in __call__
    raise exc
  File "/home/utkarshr_ug22_cs/QuantasticaAPI/ai/.venv/lib/python3.11/site-packages/starlette/middleware/errors.py", line 164, in __call__
    await self.app(scope, receive, _send)
  File "/home/utkarshr_ug22_cs/QuantasticaAPI/ai/.venv/lib/python3.11/site-packages/starlette/middleware/exceptions.py", line 63, in __call__
    await wrap_app_handling_exceptions(self.app, conn)(scope, receive, send)
  File "/home/utkarshr_ug22_cs/QuantasticaAPI/ai/.venv/lib/python3.11/site-packages/starlette/_exception_handler.py", line 53, in wrapped_app
    raise exc
  File "/home/utkarshr_ug22_cs/QuantasticaAPI/ai/.venv/lib/python3.11/site-packages/starlette/_exception_handler.py", line 42, in wrapped_app
    await app(scope, receive, sender)
  File "/home/utkarshr_ug22_cs/QuantasticaAPI/ai/.venv/lib/python3.11/site-packages/starlette/routing.py", line 716, in __call__
    await self.middleware_stack(scope, receive, send)
  File "/home/utkarshr_ug22_cs/QuantasticaAPI/ai/.venv/lib/python3.11/site-packages/starlette/routing.py", line 736, in app
    await route.handle(scope, receive, send)
  File "/home/utkarshr_ug22_cs/QuantasticaAPI/ai/.venv/lib/python3.11/site-packages/starlette/routing.py", line 290, in handle
    await self.app(scope, receive, send)
  File "/home/utkarshr_ug22_cs/QuantasticaAPI/ai/.venv/lib/python3.11/site-packages/starlette/routing.py", line 78, in app
    await wrap_app_handling_exceptions(app, request)(scope, receive, send)
  File "/home/utkarshr_ug22_cs/QuantasticaAPI/ai/.venv/lib/python3.11/site-packages/starlette/_exception_handler.py", line 53, in wrapped_app
    raise exc
  File "/home/utkarshr_ug22_cs/QuantasticaAPI/ai/.venv/lib/python3.11/site-packages/starlette/_exception_handler.py", line 42, in wrapped_app
    await app(scope, receive, sender)
  File "/home/utkarshr_ug22_cs/QuantasticaAPI/ai/.venv/lib/python3.11/site-packages/starlette/routing.py", line 75, in app
    response = await f(request)
               ^^^^^^^^^^^^^^^^
  File "/home/utkarshr_ug22_cs/QuantasticaAPI/ai/.venv/lib/python3.11/site-packages/fastapi/routing.py", line 302, in app
    raw_response = await run_endpoint_function(
                   ^^^^^^^^^^^^^^^^^^^^^^^^^^^^
  File "/home/utkarshr_ug22_cs/QuantasticaAPI/ai/.venv/lib/python3.11/site-packages/fastapi/routing.py", line 215, in run_endpoint_function
    return await run_in_threadpool(dependant.call, **values)
           ^^^^^^^^^^^^^^^^^^^^^^^^^^^^^^^^^^^^^^^^^^^^^^^^^
  File "/home/utkarshr_ug22_cs/QuantasticaAPI/ai/.venv/lib/python3.11/site-packages/starlette/concurrency.py", line 38, in run_in_threadpool
    return await anyio.to_thread.run_sync(func)
           ^^^^^^^^^^^^^^^^^^^^^^^^^^^^^^^^^^^^
  File "/home/utkarshr_ug22_cs/QuantasticaAPI/ai/.venv/lib/python3.11/site-packages/anyio/to_thread.py", line 56, in run_sync
    return await get_async_backend().run_sync_in_worker_thread(
           ^^^^^^^^^^^^^^^^^^^^^^^^^^^^^^^^^^^^^^^^^^^^^^^^^^^^
  File "/home/utkarshr_ug22_cs/QuantasticaAPI/ai/.venv/lib/python3.11/site-packages/anyio/_backends/_asyncio.py", line 2470, in run_sync_in_worker_thread
    return await future
           ^^^^^^^^^^^^
  File "/home/utkarshr_ug22_cs/QuantasticaAPI/ai/.venv/lib/python3.11/site-packages/anyio/_backends/_asyncio.py", line 967, in run
    result = context.run(func, *args)
             ^^^^^^^^^^^^^^^^^^^^^^^^
  File "/home/utkarshr_ug22_cs/QuantasticaAPI/ai/app/api/routes/prompt.py", line 31, in accept_prompt
    session_id = create_or_get_session(req.user_id)
                 ^^^^^^^^^^^^^^^^^^^^^^^^^^^^^^^^^^
  File "/home/utkarshr_ug22_cs/QuantasticaAPI/ai/app/api/sessions/session.py", line 22, in create_or_get_session
    response = requests.post(url)
               ^^^^^^^^^^^^^^^^^^
  File "/home/utkarshr_ug22_cs/QuantasticaAPI/ai/.venv/lib/python3.11/site-packages/requests/api.py", line 115, in post
    return request("post", url, data=data, json=json, **kwargs)
           ^^^^^^^^^^^^^^^^^^^^^^^^^^^^^^^^^^^^^^^^^^^^^^^^^^^^
  File "/home/utkarshr_ug22_cs/QuantasticaAPI/ai/.venv/lib/python3.11/site-packages/requests/api.py", line 59, in request
    return session.request(method=method, url=url, **kwargs)
           ^^^^^^^^^^^^^^^^^^^^^^^^^^^^^^^^^^^^^^^^^^^^^^^^^
  File "/home/utkarshr_ug22_cs/QuantasticaAPI/ai/.venv/lib/python3.11/site-packages/requests/sessions.py", line 575, in request
    prep = self.prepare_request(req)
           ^^^^^^^^^^^^^^^^^^^^^^^^^
  File "/home/utkarshr_ug22_cs/QuantasticaAPI/ai/.venv/lib/python3.11/site-packages/requests/sessions.py", line 484, in prepare_request
    p.prepare(
  File "/home/utkarshr_ug22_cs/QuantasticaAPI/ai/.venv/lib/python3.11/site-packages/requests/models.py", line 367, in prepare
    self.prepare_url(url, params)
  File "/home/utkarshr_ug22_cs/QuantasticaAPI/ai/.venv/lib/python3.11/site-packages/requests/models.py", line 438, in prepare_url
    raise MissingSchema(
requests.exceptions.MissingSchema: Invalid URL 'None/apps/financial_news_analyzer/users/u_124/sessions/s_ddd5a866': No scheme supplied. Perhaps you meant https://None/apps/financial_news_analyzer/users/u_124/sessions/s_ddd5a866?
INFO:     223.237.160.83:39231 - "POST /prompt/financial_analyzer HTTP/1.1" 500 Internal Server Error
ERROR:    Exception in ASGI application
Traceback (most recent call last):
  File "/home/utkarshr_ug22_cs/QuantasticaAPI/ai/.venv/lib/python3.11/site-packages/uvicorn/protocols/http/h11_impl.py", line 403, in run_asgi
    result = await app(  # type: ignore[func-returns-value]
             ^^^^^^^^^^^^^^^^^^^^^^^^^^^^^^^^^^^^^^^^^^^^^^
  File "/home/utkarshr_ug22_cs/QuantasticaAPI/ai/.venv/lib/python3.11/site-packages/uvicorn/middleware/proxy_headers.py", line 60, in __call__
    return await self.app(scope, receive, send)
           ^^^^^^^^^^^^^^^^^^^^^^^^^^^^^^^^^^^^
  File "/home/utkarshr_ug22_cs/QuantasticaAPI/ai/.venv/lib/python3.11/site-packages/fastapi/applications.py", line 1054, in __call__
    await super().__call__(scope, receive, send)
  File "/home/utkarshr_ug22_cs/QuantasticaAPI/ai/.venv/lib/python3.11/site-packages/starlette/applications.py", line 113, in __call__
    await self.middleware_stack(scope, receive, send)
  File "/home/utkarshr_ug22_cs/QuantasticaAPI/ai/.venv/lib/python3.11/site-packages/starlette/middleware/errors.py", line 186, in __call__
    raise exc
  File "/home/utkarshr_ug22_cs/QuantasticaAPI/ai/.venv/lib/python3.11/site-packages/starlette/middleware/errors.py", line 164, in __call__
    await self.app(scope, receive, _send)
  File "/home/utkarshr_ug22_cs/QuantasticaAPI/ai/.venv/lib/python3.11/site-packages/starlette/middleware/exceptions.py", line 63, in __call__
    await wrap_app_handling_exceptions(self.app, conn)(scope, receive, send)
  File "/home/utkarshr_ug22_cs/QuantasticaAPI/ai/.venv/lib/python3.11/site-packages/starlette/_exception_handler.py", line 53, in wrapped_app
    raise exc
  File "/home/utkarshr_ug22_cs/QuantasticaAPI/ai/.venv/lib/python3.11/site-packages/starlette/_exception_handler.py", line 42, in wrapped_app
    await app(scope, receive, sender)
  File "/home/utkarshr_ug22_cs/QuantasticaAPI/ai/.venv/lib/python3.11/site-packages/starlette/routing.py", line 716, in __call__
    await self.middleware_stack(scope, receive, send)
  File "/home/utkarshr_ug22_cs/QuantasticaAPI/ai/.venv/lib/python3.11/site-packages/starlette/routing.py", line 736, in app
    await route.handle(scope, receive, send)
  File "/home/utkarshr_ug22_cs/QuantasticaAPI/ai/.venv/lib/python3.11/site-packages/starlette/routing.py", line 290, in handle
    await self.app(scope, receive, send)
  File "/home/utkarshr_ug22_cs/QuantasticaAPI/ai/.venv/lib/python3.11/site-packages/starlette/routing.py", line 78, in app
    await wrap_app_handling_exceptions(app, request)(scope, receive, send)
  File "/home/utkarshr_ug22_cs/QuantasticaAPI/ai/.venv/lib/python3.11/site-packages/starlette/_exception_handler.py", line 53, in wrapped_app
    raise exc
  File "/home/utkarshr_ug22_cs/QuantasticaAPI/ai/.venv/lib/python3.11/site-packages/starlette/_exception_handler.py", line 42, in wrapped_app
    await app(scope, receive, sender)
  File "/home/utkarshr_ug22_cs/QuantasticaAPI/ai/.venv/lib/python3.11/site-packages/starlette/routing.py", line 75, in app
    response = await f(request)
               ^^^^^^^^^^^^^^^^
  File "/home/utkarshr_ug22_cs/QuantasticaAPI/ai/.venv/lib/python3.11/site-packages/fastapi/routing.py", line 302, in app
    raw_response = await run_endpoint_function(
                   ^^^^^^^^^^^^^^^^^^^^^^^^^^^^
  File "/home/utkarshr_ug22_cs/QuantasticaAPI/ai/.venv/lib/python3.11/site-packages/fastapi/routing.py", line 215, in run_endpoint_function
    return await run_in_threadpool(dependant.call, **values)
           ^^^^^^^^^^^^^^^^^^^^^^^^^^^^^^^^^^^^^^^^^^^^^^^^^
  File "/home/utkarshr_ug22_cs/QuantasticaAPI/ai/.venv/lib/python3.11/site-packages/starlette/concurrency.py", line 38, in run_in_threadpool
    return await anyio.to_thread.run_sync(func)
           ^^^^^^^^^^^^^^^^^^^^^^^^^^^^^^^^^^^^
  File "/home/utkarshr_ug22_cs/QuantasticaAPI/ai/.venv/lib/python3.11/site-packages/anyio/to_thread.py", line 56, in run_sync
    return await get_async_backend().run_sync_in_worker_thread(
           ^^^^^^^^^^^^^^^^^^^^^^^^^^^^^^^^^^^^^^^^^^^^^^^^^^^^
  File "/home/utkarshr_ug22_cs/QuantasticaAPI/ai/.venv/lib/python3.11/site-packages/anyio/_backends/_asyncio.py", line 2470, in run_sync_in_worker_thread
    return await future
           ^^^^^^^^^^^^
  File "/home/utkarshr_ug22_cs/QuantasticaAPI/ai/.venv/lib/python3.11/site-packages/anyio/_backends/_asyncio.py", line 967, in run
    result = context.run(func, *args)
             ^^^^^^^^^^^^^^^^^^^^^^^^
  File "/home/utkarshr_ug22_cs/QuantasticaAPI/ai/app/api/routes/prompt.py", line 41, in accept_prompt
    resp = requests.post(url, json=payload)
           ^^^^^^^^^^^^^^^^^^^^^^^^^^^^^^^^
  File "/home/utkarshr_ug22_cs/QuantasticaAPI/ai/.venv/lib/python3.11/site-packages/requests/api.py", line 115, in post
    return request("post", url, data=data, json=json, **kwargs)
           ^^^^^^^^^^^^^^^^^^^^^^^^^^^^^^^^^^^^^^^^^^^^^^^^^^^^
  File "/home/utkarshr_ug22_cs/QuantasticaAPI/ai/.venv/lib/python3.11/site-packages/requests/api.py", line 59, in request
    return session.request(method=method, url=url, **kwargs)
           ^^^^^^^^^^^^^^^^^^^^^^^^^^^^^^^^^^^^^^^^^^^^^^^^^
  File "/home/utkarshr_ug22_cs/QuantasticaAPI/ai/.venv/lib/python3.11/site-packages/requests/sessions.py", line 575, in request
    prep = self.prepare_request(req)
           ^^^^^^^^^^^^^^^^^^^^^^^^^
  File "/home/utkarshr_ug22_cs/QuantasticaAPI/ai/.venv/lib/python3.11/site-packages/requests/sessions.py", line 484, in prepare_request
    p.prepare(
  File "/home/utkarshr_ug22_cs/QuantasticaAPI/ai/.venv/lib/python3.11/site-packages/requests/models.py", line 367, in prepare
    self.prepare_url(url, params)
  File "/home/utkarshr_ug22_cs/QuantasticaAPI/ai/.venv/lib/python3.11/site-packages/requests/models.py", line 438, in prepare_url
    raise MissingSchema(
requests.exceptions.MissingSchema: Invalid URL 'None/run': No scheme supplied. Perhaps you meant https://None/run?
INFO:     223.237.160.83:34581 - "POST /session/financial_analyzer/user_125 HTTP/1.1" 404 Not Found
INFO:     223.237.160.83:38482 - "POST /sessions/financial_analyzer/user_125 HTTP/1.1" 500 Internal Server Error
ERROR:    Exception in ASGI application
Traceback (most recent call last):
  File "/home/utkarshr_ug22_cs/QuantasticaAPI/ai/.venv/lib/python3.11/site-packages/uvicorn/protocols/http/h11_impl.py", line 403, in run_asgi
    result = await app(  # type: ignore[func-returns-value]
             ^^^^^^^^^^^^^^^^^^^^^^^^^^^^^^^^^^^^^^^^^^^^^^
  File "/home/utkarshr_ug22_cs/QuantasticaAPI/ai/.venv/lib/python3.11/site-packages/uvicorn/middleware/proxy_headers.py", line 60, in __call__
    return await self.app(scope, receive, send)
           ^^^^^^^^^^^^^^^^^^^^^^^^^^^^^^^^^^^^
  File "/home/utkarshr_ug22_cs/QuantasticaAPI/ai/.venv/lib/python3.11/site-packages/fastapi/applications.py", line 1054, in __call__
    await super().__call__(scope, receive, send)
  File "/home/utkarshr_ug22_cs/QuantasticaAPI/ai/.venv/lib/python3.11/site-packages/starlette/applications.py", line 113, in __call__
    await self.middleware_stack(scope, receive, send)
  File "/home/utkarshr_ug22_cs/QuantasticaAPI/ai/.venv/lib/python3.11/site-packages/starlette/middleware/errors.py", line 186, in __call__
    raise exc
  File "/home/utkarshr_ug22_cs/QuantasticaAPI/ai/.venv/lib/python3.11/site-packages/starlette/middleware/errors.py", line 164, in __call__
    await self.app(scope, receive, _send)
  File "/home/utkarshr_ug22_cs/QuantasticaAPI/ai/.venv/lib/python3.11/site-packages/starlette/middleware/exceptions.py", line 63, in __call__
    await wrap_app_handling_exceptions(self.app, conn)(scope, receive, send)
  File "/home/utkarshr_ug22_cs/QuantasticaAPI/ai/.venv/lib/python3.11/site-packages/starlette/_exception_handler.py", line 53, in wrapped_app
    raise exc
  File "/home/utkarshr_ug22_cs/QuantasticaAPI/ai/.venv/lib/python3.11/site-packages/starlette/_exception_handler.py", line 42, in wrapped_app
    await app(scope, receive, sender)
  File "/home/utkarshr_ug22_cs/QuantasticaAPI/ai/.venv/lib/python3.11/site-packages/starlette/routing.py", line 716, in __call__
    await self.middleware_stack(scope, receive, send)
  File "/home/utkarshr_ug22_cs/QuantasticaAPI/ai/.venv/lib/python3.11/site-packages/starlette/routing.py", line 736, in app
    await route.handle(scope, receive, send)
  File "/home/utkarshr_ug22_cs/QuantasticaAPI/ai/.venv/lib/python3.11/site-packages/starlette/routing.py", line 290, in handle
    await self.app(scope, receive, send)
  File "/home/utkarshr_ug22_cs/QuantasticaAPI/ai/.venv/lib/python3.11/site-packages/starlette/routing.py", line 78, in app
    await wrap_app_handling_exceptions(app, request)(scope, receive, send)
  File "/home/utkarshr_ug22_cs/QuantasticaAPI/ai/.venv/lib/python3.11/site-packages/starlette/_exception_handler.py", line 53, in wrapped_app
    raise exc
  File "/home/utkarshr_ug22_cs/QuantasticaAPI/ai/.venv/lib/python3.11/site-packages/starlette/_exception_handler.py", line 42, in wrapped_app
    await app(scope, receive, sender)
  File "/home/utkarshr_ug22_cs/QuantasticaAPI/ai/.venv/lib/python3.11/site-packages/starlette/routing.py", line 75, in app
    response = await f(request)
               ^^^^^^^^^^^^^^^^
  File "/home/utkarshr_ug22_cs/QuantasticaAPI/ai/.venv/lib/python3.11/site-packages/fastapi/routing.py", line 302, in app
    raw_response = await run_endpoint_function(
                   ^^^^^^^^^^^^^^^^^^^^^^^^^^^^
  File "/home/utkarshr_ug22_cs/QuantasticaAPI/ai/.venv/lib/python3.11/site-packages/fastapi/routing.py", line 215, in run_endpoint_function
    return await run_in_threadpool(dependant.call, **values)
           ^^^^^^^^^^^^^^^^^^^^^^^^^^^^^^^^^^^^^^^^^^^^^^^^^
  File "/home/utkarshr_ug22_cs/QuantasticaAPI/ai/.venv/lib/python3.11/site-packages/starlette/concurrency.py", line 38, in run_in_threadpool
    return await anyio.to_thread.run_sync(func)
           ^^^^^^^^^^^^^^^^^^^^^^^^^^^^^^^^^^^^
  File "/home/utkarshr_ug22_cs/QuantasticaAPI/ai/.venv/lib/python3.11/site-packages/anyio/to_thread.py", line 56, in run_sync
    return await get_async_backend().run_sync_in_worker_thread(
           ^^^^^^^^^^^^^^^^^^^^^^^^^^^^^^^^^^^^^^^^^^^^^^^^^^^^
  File "/home/utkarshr_ug22_cs/QuantasticaAPI/ai/.venv/lib/python3.11/site-packages/anyio/_backends/_asyncio.py", line 2470, in run_sync_in_worker_thread
    return await future
           ^^^^^^^^^^^^
  File "/home/utkarshr_ug22_cs/QuantasticaAPI/ai/.venv/lib/python3.11/site-packages/anyio/_backends/_asyncio.py", line 967, in run
    result = context.run(func, *args)
             ^^^^^^^^^^^^^^^^^^^^^^^^
  File "/home/utkarshr_ug22_cs/QuantasticaAPI/ai/app/api/sessions/session.py", line 22, in create_or_get_session
    response = requests.post(url)
               ^^^^^^^^^^^^^^^^^^
  File "/home/utkarshr_ug22_cs/QuantasticaAPI/ai/.venv/lib/python3.11/site-packages/requests/api.py", line 115, in post
    return request("post", url, data=data, json=json, **kwargs)
           ^^^^^^^^^^^^^^^^^^^^^^^^^^^^^^^^^^^^^^^^^^^^^^^^^^^^
  File "/home/utkarshr_ug22_cs/QuantasticaAPI/ai/.venv/lib/python3.11/site-packages/requests/api.py", line 59, in request
    return session.request(method=method, url=url, **kwargs)
           ^^^^^^^^^^^^^^^^^^^^^^^^^^^^^^^^^^^^^^^^^^^^^^^^^
  File "/home/utkarshr_ug22_cs/QuantasticaAPI/ai/.venv/lib/python3.11/site-packages/requests/sessions.py", line 575, in request
    prep = self.prepare_request(req)
           ^^^^^^^^^^^^^^^^^^^^^^^^^
  File "/home/utkarshr_ug22_cs/QuantasticaAPI/ai/.venv/lib/python3.11/site-packages/requests/sessions.py", line 484, in prepare_request
    p.prepare(
  File "/home/utkarshr_ug22_cs/QuantasticaAPI/ai/.venv/lib/python3.11/site-packages/requests/models.py", line 367, in prepare
    self.prepare_url(url, params)
  File "/home/utkarshr_ug22_cs/QuantasticaAPI/ai/.venv/lib/python3.11/site-packages/requests/models.py", line 438, in prepare_url
    raise MissingSchema(
requests.exceptions.MissingSchema: Invalid URL 'None/apps/financial_news_analyzer/users/user_125/sessions/s_23b1b393': No scheme supplied. Perhaps you meant https://None/apps/financial_news_analyzer/users/user_125/sessions/s_23b1b393?
INFO:     Shutting down
INFO:     Waiting for application shutdown.
INFO:     Application shutdown complete.
INFO:     Finished server process [37549]
INFO:     Stopping reloader process [37547]
INFO:     Will watch for changes in these directories: ['/home/utkarshr_ug22_cs/QuantasticaAPI/ai']
INFO:     Uvicorn running on http://0.0.0.0:8001 (Press CTRL+C to quit)
INFO:     Started reloader process [41386] using StatReload
INFO:     Started server process [41388]
INFO:     Waiting for application startup.
INFO:     Application startup complete.
INFO:     223.237.160.83:27101 - "POST /prompt/financial_analyzer/ HTTP/1.1" 307 Temporary Redirect
<Response [200]>
INFO:     223.237.160.83:27101 - "POST /prompt/financial_analyzer HTTP/1.1" 200 OK
